#VRML_SIM R2019a utf8
WorldInfo {
}
Viewpoint {
  orientation 0 1 0 0
  position 0.03449821261292902 0.1061593527649402 0.47132999486696026
}
TexturedBackground {
}
TexturedBackgroundLight {
}
Floor {
}
Robot {
  translation 0 0.08 0
  children [
    Shape {
      appearance PBRAppearance {
        baseColor 0.8 0 0
        roughness 1
        metalness 0
      }
      geometry Box {
        size 0.25 0.08 0.1
      }
    }
    HingeJoint {
      jointParameters HingeJointParameters {
        axis 0 0 1
        anchor -0.05 0 0.065
      }
      endPoint Solid {
        translation -0.05 0 0.065
        rotation 1 0 0 1.5707996938995747
        children [
          Shape {
            appearance DEF BLACK PBRAppearance {
              baseColor 0 0 0
              roughness 1
              metalness 0
            }
            geometry DEF WHEEL1 Cylinder {
              height 0.03
              radius 0.075
            }
          }
        ]
      }
    }
    HingeJoint {
      jointParameters HingeJointParameters {
        axis 0 0 1
        anchor -0.05 0 -0.065
      }
      endPoint Solid {
        translation -0.05 0 -0.065
        rotation 1 0 0 1.5707996938995747
        children [
          Shape {
            appearance USE BLACK
            geometry USE WHEEL1
          }
        ]
        name "solid(1)"
      }
    }
    Transform {
      translation 0.1075 -0.0575 0
      children [
        Shape {
          appearance PBRAppearance {
            baseColor 0.9882352941176471 0.9137254901960784 0.30980392156862746
            roughness 1
            metalness 0
          }
          geometry Sphere {
            radius 0.0175
          }
        }
      ]
    }
  ]
}
