#VRML_SIM R2019a utf8
WorldInfo {
}
Viewpoint {
  orientation -0.5144575139554322 0.8436615796104558 0.15352070031102225 0.6799548540976252
  position 0.43710298910441714 0.4073051058541829 0.7441995660660161
}
TexturedBackground {
}
TexturedBackgroundLight {
}
Floor {
}
Robot {
  translation 0 0.08 0
  children [
    DEF SH_BODY Group {
      children [
        Shape {
          appearance PBRAppearance {
            baseColor 0.8 0 0
            roughness 1
            metalness 0
          }
          geometry Box {
            size 0.25 0.08 0.1
          }
        }
        Transform {
          translation 0.1075 -0.0575 0
          children [
            Shape {
              appearance PBRAppearance {
                baseColor 0.9882352941176471 0.9137254901960784 0.30980392156862746
                roughness 1
                metalness 0
              }
              geometry Sphere {
                radius 0.0175
              }
            }
          ]
        }
      ]
    }
    HingeJoint {
      jointParameters HingeJointParameters {
        axis 0 0 1
        anchor -0.05 0 0.065
      }
      endPoint Solid {
        translation -0.05 0 0.065
        rotation 1 0 0 1.5707996938995747
        children [
          Shape {
            appearance DEF BLACK PBRAppearance {
              baseColor 0 0 0
              roughness 1
              metalness 0
            }
            geometry DEF WHEEL1 Cylinder {
              height 0.03
              radius 0.075
            }
          }
        ]
        boundingObject USE WHEEL1
        physics Physics {
        }
      }
    }
    HingeJoint {
      jointParameters HingeJointParameters {
        axis 0 0 1
        anchor -0.05 0 -0.065
      }
      endPoint Solid {
        translation -0.05 0 -0.065
        rotation 1 0 0 1.5707996938995747
        children [
          Shape {
            appearance USE BLACK
            geometry USE WHEEL1
          }
        ]
        name "solid(1)"
        boundingObject USE WHEEL1
        physics Physics {
        }
      }
    }
  ]
  boundingObject USE SH_BODY
  physics Physics {
  }
}
